{
 "cells": [
  {
   "cell_type": "code",
   "execution_count": 1,
   "metadata": {},
   "outputs": [
    {
     "name": "stdout",
     "output_type": "stream",
     "text": [
      "^C\n"
     ]
    },
    {
     "name": "stdout",
     "output_type": "stream",
     "text": [
      "Collecting gdrivefs\n",
      "  Using cached gdrivefs-0.14.13.tar.gz (71 kB)\n",
      "  Installing build dependencies: started\n",
      "  Installing build dependencies: still running...\n",
      "  Installing build dependencies: still running...\n",
      "  Installing build dependencies: still running...\n",
      "  Installing build dependencies: still running...\n",
      "  Installing build dependencies: still running...\n",
      "  Installing build dependencies: still running...\n",
      "  Installing build dependencies: finished with status 'error'\n"
     ]
    },
    {
     "name": "stderr",
     "output_type": "stream",
     "text": [
      "  error: subprocess-exited-with-error\n",
      "  \n",
      "  × pip subprocess to install build dependencies did not run successfully.\n",
      "  │ exit code: 1\n",
      "  ╰─> [7 lines of output]\n",
      "      WARNING: Retrying (Retry(total=4, connect=None, read=None, redirect=None, status=None)) after connection broken by 'ConnectTimeoutError(<pip._vendor.urllib3.connection.HTTPSConnection object at 0x000001ECDAC688E0>, 'Connection to pypi.org timed out. (connect timeout=15)')': /simple/setuptools/\n",
      "      WARNING: Retrying (Retry(total=3, connect=None, read=None, redirect=None, status=None)) after connection broken by 'ConnectTimeoutError(<pip._vendor.urllib3.connection.HTTPSConnection object at 0x000001ECDAC68BB0>, 'Connection to pypi.org timed out. (connect timeout=15)')': /simple/setuptools/\n",
      "      WARNING: Retrying (Retry(total=2, connect=None, read=None, redirect=None, status=None)) after connection broken by 'ConnectTimeoutError(<pip._vendor.urllib3.connection.HTTPSConnection object at 0x000001ECDAC68EB0>, 'Connection to pypi.org timed out. (connect timeout=15)')': /simple/setuptools/\n",
      "      WARNING: Retrying (Retry(total=1, connect=None, read=None, redirect=None, status=None)) after connection broken by 'ConnectTimeoutError(<pip._vendor.urllib3.connection.HTTPSConnection object at 0x000001ECDAC68F70>, 'Connection to pypi.org timed out. (connect timeout=15)')': /simple/setuptools/\n",
      "      WARNING: Retrying (Retry(total=0, connect=None, read=None, redirect=None, status=None)) after connection broken by 'ConnectTimeoutError(<pip._vendor.urllib3.connection.HTTPSConnection object at 0x000001ECDAC9A1C0>, 'Connection to pypi.org timed out. (connect timeout=15)')': /simple/setuptools/\n",
      "      ERROR: Could not find a version that satisfies the requirement setuptools>=40.8.0 (from versions: none)\n",
      "      ERROR: No matching distribution found for setuptools>=40.8.0\n",
      "      [end of output]\n",
      "  \n",
      "  note: This error originates from a subprocess, and is likely not a problem with pip.\n",
      "error: subprocess-exited-with-error\n",
      "\n",
      "× pip subprocess to install build dependencies did not run successfully.\n",
      "│ exit code: 1\n",
      "╰─> See above for output.\n",
      "\n",
      "note: This error originates from a subprocess, and is likely not a problem with pip.\n"
     ]
    }
   ],
   "source": [
    "!pip install --proxy=10.203.32.190:8080 gdrivefs"
   ]
  },
  {
   "cell_type": "code",
   "execution_count": 3,
   "metadata": {},
   "outputs": [],
   "source": [
    "import pandas as pd\n",
    "import dvc.api"
   ]
  },
  {
   "cell_type": "code",
   "execution_count": 4,
   "metadata": {},
   "outputs": [
    {
     "data": {
      "text/plain": [
       "'gdrive://1n_OvHJBH6I3Xahwle1HpYjVICmT2haly/files/md5/e8/c4560161dc3c8571b5b2db25be3294'"
      ]
     },
     "execution_count": 4,
     "metadata": {},
     "output_type": "execute_result"
    }
   ],
   "source": [
    "remote = \"myremote\"\n",
    "url = dvc.api.get_url(\"data/raw_data/train.csv\", \n",
    "                      remote=remote)\n",
    "url"
   ]
  },
  {
   "cell_type": "code",
   "execution_count": 7,
   "metadata": {},
   "outputs": [
    {
     "ename": "AttributeError",
     "evalue": "'str' object has no attribute 'head'",
     "output_type": "error",
     "traceback": [
      "\u001b[1;31m---------------------------------------------------------------------------\u001b[0m",
      "\u001b[1;31mAttributeError\u001b[0m                            Traceback (most recent call last)",
      "Cell \u001b[1;32mIn[7], line 3\u001b[0m\n\u001b[0;32m      1\u001b[0m data \u001b[38;5;241m=\u001b[39m dvc\u001b[38;5;241m.\u001b[39mapi\u001b[38;5;241m.\u001b[39mread(\u001b[38;5;124m\"\u001b[39m\u001b[38;5;124mdata/raw_data/train.csv\u001b[39m\u001b[38;5;124m\"\u001b[39m, \n\u001b[0;32m      2\u001b[0m                       remote\u001b[38;5;241m=\u001b[39mremote)\n\u001b[1;32m----> 3\u001b[0m \u001b[43mdata\u001b[49m\u001b[38;5;241;43m.\u001b[39;49m\u001b[43mhead\u001b[49m()\n",
      "\u001b[1;31mAttributeError\u001b[0m: 'str' object has no attribute 'head'"
     ]
    }
   ],
   "source": [
    "data = dvc.api.read(\"data/raw_data/train.csv\", \n",
    "                      remote=remote)\n",
    "data"
   ]
  }
 ],
 "metadata": {
  "kernelspec": {
   "display_name": "Python 3",
   "language": "python",
   "name": "python3"
  },
  "language_info": {
   "codemirror_mode": {
    "name": "ipython",
    "version": 3
   },
   "file_extension": ".py",
   "mimetype": "text/x-python",
   "name": "python",
   "nbconvert_exporter": "python",
   "pygments_lexer": "ipython3",
   "version": "3.9.13"
  }
 },
 "nbformat": 4,
 "nbformat_minor": 2
}
